---
layout:     post                    # 使用的布局（不需要改）
title:      .NET TPL的使用问题(2)            # 标题 
subtitle:   TPL的异常处理  #副标题
date:       2020-03-18              # 时间
author:     Peter                      # 作者
header-img: img/post-bg-2015.jpg    #这篇文章标题背景图片
catalog: true                       # 是否归档
tags:                               #标签
    - .NET
    - Parallel
---

## 前言

TPL中task抛出的一个或者多个异常都会被包裹在`AggregateException`中抛出。随后`AggregateException`会被抛出给等待task结束或者等待返回`Result`的那个线程。  
`AggregateException`中内含可遍历的`InnerExceptions`属性，可以用来检查内部task抛出的所有异常并分别处理。

### 使用`Task.Wait/WaitAll/WaitAny`方法捕获异常

值得注意的是，`AggregateException`是在使用`Task.Wait`时抛出的，所以应该使用`try/catch`包裹该部分逻辑。  
```
using System;
using System.Threading.Tasks;

public class Example
{
   public static void Main()
   {
      var task1 = Task.Run( () => { throw new CustomException("This exception is expected!"); } );

      try
      {
          task1.Wait();
      }
      catch (AggregateException ae)
      {
          foreach (var e in ae.InnerExceptions) {
              // Handle the custom exception.
              if (e is CustomException) {
                  Console.WriteLine(e.Message);
              }
              // Rethrow any other exception.
              else {
                  throw;
              }
          }
      }
   }
}

public class CustomException : Exception
{
   public CustomException(String message) : base(message)
   {}
}
// The example displays the following output:
//        This exception is expected!
```

### 使用`Task. Exception`属性捕获异常
如果我们不使用`Task.Wait`方法来等待task的结果并捕捉`AggregateException`异常，我们可以使用`Task. Exception`属性来查看内部的异常。当一个任务是以`TaskStatus.Faulted`状态返回时，我们就可以通过查看`Task. Exception`属性来捕获并处理内部异常。  
一个best practice是通过continuation 来设置一个继承task，并且只有在先行的task返回'TaskStatus.Faulted'状态时才会执行该task.  
```
using System;
using System.Threading;
using System.Threading.Tasks;

public class Example
{
   public static void Main()
   {
      var task1 = Task.Run(() =>
                           { throw new CustomException("task1 faulted.");
      }).ContinueWith( t => { Console.WriteLine("{0}: {1}",
                                                t.Exception.InnerException.GetType().Name,
                                                t.Exception.InnerException.Message);
                            }, TaskContinuationOptions.OnlyOnFaulted);
      Thread.Sleep(500);
   }
}

public class CustomException : Exception
{
   public CustomException(String message) : base(message)
   {}
}
// The example displays output like the following:
//        CustomException: task1 faulted.
```  
### Attached Child Task异常处理

一般情况下，如果attached child task内部抛出异常，异常首先会被child task包裹为`AggregateException`并抛出，然后parent task发现异常会再次包裹`AggregateException`,这种情况在异常最终要处理时带来的影响显而易见，因此我们可以使用`Flatten`来去掉所有嵌套的`AggregateException`。  
```
using System;
using System.Threading.Tasks;

public class Example
{
   public static void Main()
   {
      var task1 = Task.Factory.StartNew(() => {
                     var child1 = Task.Factory.StartNew(() => {
                        var child2 = Task.Factory.StartNew(() => {
                            // This exception is nested inside three AggregateExceptions.
                            throw new CustomException("Attached child2 faulted.");
                        }, TaskCreationOptions.AttachedToParent);

                        // This exception is nested inside two AggregateExceptions.
                        throw new CustomException("Attached child1 faulted.");
                     }, TaskCreationOptions.AttachedToParent);
      });

      try {
         task1.Wait();
      }
      catch (AggregateException ae) {
         foreach (var e in ae.Flatten().InnerExceptions) {
            if (e is CustomException) {
               Console.WriteLine(e.Message);
            }
            else {
               throw;
            }
         }
      }
   }
}
```  

### Detached Child Task异常处理

Detached 子任务的抛出的异常**必须**被最贴近的parent任务处理，可以是handle或者rethrow。Detached 子任务抛出的异常不会像Attached异常一样，“自动”传递给最上层的父任务，并被`AggregateException`包裹。
对于Detached子任务来说，最上层的父任务可以手动地重新抛出异常，这样的话等待线程中的`try/catch`即可捕获被`AggregateException`包裹的异常。  

```
using System;
using System.Threading.Tasks;

public class Example
{
   public static void Main()
   {
      var task1 = Task.Run(() => {
                       var nested1 = Task.Run(() => {
                                          throw new CustomException("Detached child task faulted.");
                                     });

          // Here the exception will be escalated back to the calling thread.
          // We could use try/catch here to prevent that.
          nested1.Wait();
      });

      try {
         task1.Wait();
      }
      catch (AggregateException ae) {
         foreach (var e in ae.Flatten().InnerExceptions) {
            if (e is CustomException) {
               Console.WriteLine(e.Message);
            }
         }
      }
   }
}

public class CustomException : Exception
{
   public CustomException(String message) : base(message)
   {}
}
// The example displays the following output:
//    Detached child task faulted.
```

### 使用`AggregateException.Handle`方法来处理异常

`AggregateException.Handle`方法接受一个`Func<Exception,bool>`，并返回一个boolean 来说明异常有无被处理。 
```
using System;
using System.Threading.Tasks;

public class Example
{
   public static void Main()
   {
      var task1 = Task.Run( () => { throw new CustomException("This exception is expected!"); } );

      try {
          task1.Wait();
      }
      catch (AggregateException ae)
      {
         // Call the Handle method to handle the custom exception,
         // otherwise rethrow the exception.
         ae.Handle(ex => { if (ex is CustomException)
                             Console.WriteLine(ex.Message);
                          return ex is CustomException;
                        });
      }
   }
}

public class CustomException : Exception
{
   public CustomException(String message) : base(message)
   {}
}
// The example displays the following output:
//        This exception is expected!
```
如上面实例所示，`Handle`方法内判断了exception是否是`CustomException`,如果是即执行Print，如果不是则无需其余逻辑。最后返回一个Boolean来说明异常是否得到处理，如果返回的是false，异常会被重新抛出。
